Workbook

Sheet 汇总
A1: 姓名 | B1: 车厢 | C1: 是否车厢长 | D1: OHT执行30% | E1: OHT保障10% | F1: 影响力10% | G1: 努力度10% | H1: 价值分5% | I1: 总分 | J1: RANK | K1: 归属实体 | O1: 姓名 | P1: OHT-得分 | R1: 姓名 | S1: 车厢 | T1: 实体
A2: 王秉庵 | B2: =VLOOKUP(A2,R:S,2,FALSE) -> 学科工具 | C2: 否 | D2: =VLOOKUP(A2,'OHT执行（30%）'!$A:$G,7,FALSE) -> 9.5339797 | E2: =VLOOKUP(A2,'保障-(10%)'!$A:$G,7,FALSE) -> 8.7788073 | F2: =IFERROR(VLOOKUP(A2,'影响力-(10%)'!$A$1:$E$55,5,FALSE),AVERAGE('影响力-(10%)'!$E$2:$E$55)) -> 10 | G2: =VLOOKUP(A2,'努力度(10%)'!$A$1:$C$62,3,FALSE) -> 10 | H2: =VLOOKUP(A2,'系统价值分（5%）'!A:D,4,FALSE) -> 10 | I2: =(0.3*D2+0.1*E2+0.1*F2+0.1*G2+H2*0.05)/0.65 -> 9.5970379 | J2: =COUNTIF(I:I,">"&I2)+1 -> 1 | K2: =VLOOKUP(A2,$R:$T,3,FALSE()) -> RD | O2: 刘昊恺 | R2: 丁星杰 | S2: 站内营销 | T2: FE
A3: 王瑞娟 | B3: =VLOOKUP(A3,R:S,2,FALSE) -> 学科工具 | C3: 否 | D3: =VLOOKUP(A3,'OHT执行（30%）'!$A:$G,7,FALSE) -> 9.1982566 | E3: =VLOOKUP(A3,'保障-(10%)'!$A:$G,7,FALSE) -> 8.1554306 | F3: =IFERROR(VLOOKUP(A3,'影响力-(10%)'!$A$1:$E$55,5,FALSE),AVERAGE('影响力-(10%)'!$E$2:$E$55)) -> 10 | G3: =VLOOKUP(A3,'努力度(10%)'!$A$1:$C$62,3,FALSE) -> 10 | H3: =VLOOKUP(A3,'系统价值分（5%）'!A:D,4,FALSE) -> 10 | I3: =(0.3*D3+0.1*E3+0.1*F3+0.1*G3+H3*0.05)/0.65 -> 9.3461847 | J3: =COUNTIF(I:I,">"&I3)+1 -> 2 | K3: =VLOOKUP(A3,$R:$T,3,FALSE()) -> QA | O3: 王丽萍 | R3: 闫涛 | S3: 站内营销 | T3: FE
A4: 陈士卿 | B4: =VLOOKUP(A4,R:S,2,FALSE) -> 三方能力 | C4: 是 | D4: =VLOOKUP(A4,'OHT执行（30%）'!$A:$G,7,FALSE) -> 9.4983491 | E4: =VLOOKUP(A4,'保障-(10%)'!$A:$G,7,FALSE) -> 8.2960508 | F4: =IFERROR(VLOOKUP(A4,'影响力-(10%)'!$A$1:$E$55,5,FALSE),AVERAGE('影响力-(10%)'!$E$2:$E$55)) -> 10 | G4: =VLOOKUP(A4,'努力度(10%)'!$A$1:$C$62,3,FALSE) -> 8.9 | H4: =VLOOKUP(A4,'系统价值分（5%）'!A:D,4,FALSE) -> 10 | I4: =(0.3*D4+0.1*E4+0.1*F4+0.1*G4+H4*0.05)/0.65 -> 9.337092 | J4: =COUNTIF(I:I,">"&I4)+1 -> 3 | K4: =VLOOKUP(A4,$R:$T,3,FALSE()) -> RD | O4: 郭相磊 | R4: 高亦非 | S4: 站内营销 | T4: FE
A5: 王丽萍 | B5: =VLOOKUP(A5,R:S,2,FALSE) -> 督导学 | C5: 否 | D5: =VLOOKUP(A5,'OHT执行（30%）'!$A:$G,7,FALSE) -> 9.3600005 | E5: =VLOOKUP(A5,'保障-(10%)'!$A:$G,7,FALSE) -> 8.0389695 | F5: =IFERROR(VLOOKUP(A5,'影响力-(10%)'!$A$1:$E$55,5,FALSE),AVERAGE('影响力-(10%)'!$E$2:$E$55)) -> 10 | G5: =VLOOKUP(A5,'努力度(10%)'!$A$1:$C$62,3,FALSE) -> 9.52 | H5: =VLOOKUP(A5,'系统价值分（5%）'!A:D,4,FALSE) -> 9.49 | I5: =(0.3*D5+0.1*E5+0.1*F5+0.1*G5+H5*0.05)/0.65 -> 9.2898417 | J5: =COUNTIF(I:I,">"&I5)+1 -> 4 | K5: =VLOOKUP(A5,$R:$T,3,FALSE()) -> FE | O5: 谷继显 | R5: 朱静娜 | S5: 站内营销 | T5: RD
A6: 刘昊恺 | B6: =VLOOKUP(A6,R:S,2,FALSE) -> 站内营销 | C6: 否 | D6: =VLOOKUP(A6,'OHT执行（30%）'!$A:$G,7,FALSE) -> 8.9772847 | E6: =VLOOKUP(A6,'保障-(10%)'!$A:$G,7,FALSE) -> 8.2285322 | F6: =IFERROR(VLOOKUP(A6,'影响力-(10%)'!$A$1:$E$55,5,FALSE),AVERAGE('影响力-(10%)'!$E$2:$E$55)) -> 10 | G6: =VLOOKUP(A6,'努力度(10%)'!$A$1:$C$62,3,FALSE) -> 10 | H6: =VLOOKUP(A6,'系统价值分（5%）'!A:D,4,FALSE) -> 10 | I6: =(0.3*D6+0.1*E6+0.1*F6+0.1*G6+H6*0.05)/0.65 -> 9.255444 | J6: =COUNTIF(I:I,">"&I6)+1 -> 5 | K6: =VLOOKUP(A6,$R:$T,3,FALSE()) -> RD | O6: 王秉庵 | R6: 王秉庵 | S6: 学科工具 | T6: RD
A7: 朱静娜 | B7: =VLOOKUP(A7,R:S,2,FALSE) -> 站内营销 | C7: 否 | D7: =VLOOKUP(A7,'OHT执行（30%）'!$A:$G,7,FALSE) -> 8.9116973 | E7: =VLOOKUP(A7,'保障-(10%)'!$A:$G,7,FALSE) -> 8.3541741 | F7: =IFERROR(VLOOKUP(A7,'影响力-(10%)'!$A$1:$E$55,5,FALSE),AVERAGE('影响力-(10%)'!$E$2:$E$55)) -> 10 | G7: =VLOOKUP(A7,'努力度(10%)'!$A$1:$C$62,3,FALSE) -> 9.7 | H7: =VLOOKUP(A7,'系统价值分（5%）'!A:D,4,FALSE) -> 10 | I7: =(0.3*D7+0.1*E7+0.1*F7+0.1*G7+H7*0.05)/0.65 -> 9.1983486 | J7: =COUNTIF(I:I,">"&I7)+1 -> 6 | K7: =VLOOKUP(A7,$R:$T,3,FALSE()) -> RD | O7: 熊苓军 | R7: 李阔 | S7: 站内营销 | T7: PM
A8: 郭亚奎 | B8: =VLOOKUP(A8,R:S,2,FALSE) -> 站台 | C8: 否 | D8: =VLOOKUP(A8,'OHT执行（30%）'!$A:$G,7,FALSE) -> 9.1951419 | E8: =VLOOKUP(A8,'保障-(10%)'!$A:$G,7,FALSE) -> 8.2 | F8: =IFERROR(VLOOKUP(A8,'影响力-(10%)'!$A$1:$E$55,5,FALSE),AVERAGE('影响力-(10%)'!$E$2:$E$55)) -> 10 | G8: =VLOOKUP(A8,'努力度(10%)'!$A$1:$C$62,3,FALSE) -> 10 | H8: =VLOOKUP(A8,'系统价值分（5%）'!A:D,4,FALSE) -> 8 | I8: =(0.3*D8+0.1*E8+0.1*F8+0.1*G8+H8*0.05)/0.65 -> 9.1977578 | J8: =COUNTIF(I:I,">"&I8)+1 -> 7 | K8: =VLOOKUP(A8,$R:$T,3,FALSE()) -> FE | O8: 刘志伟 | R8: 王静 | S8: 三方能力 | T8: PM
A9: 熊苓军 | B9: =VLOOKUP(A9,R:S,2,FALSE) -> 站台 | C9: 否 | D9: =VLOOKUP(A9,'OHT执行（30%）'!$A:$G,7,FALSE) -> 9.1831138 | E9: =VLOOKUP(A9,'保障-(10%)'!$A:$G,7,FALSE) -> 8.2 | F9: =IFERROR(VLOOKUP(A9,'影响力-(10%)'!$A$1:$E$55,5,FALSE),AVERAGE('影响力-(10%)'!$E$2:$E$55)) -> 10 | G9: =VLOOKUP(A9,'努力度(10%)'!$A$1:$C$62,3,FALSE) -> 10 | H9: =VLOOKUP(A9,'系统价值分（5%）'!A:D,4,FALSE) -> 8 | I9: =(0.3*D9+0.1*E9+0.1*F9+0.1*G9+H9*0.05)/0.65 -> 9.1922064 | J9: =COUNTIF(I:I,">"&I9)+1 -> 8 | K9: =VLOOKUP(A9,$R:$T,3,FALSE()) -> FE | O9: 茆伟 | R9: 李红苗 | S9: 三方能力 | T9: QA
A10: 李占旭 | B10: =VLOOKUP(A10,R:S,2,FALSE) -> 站台 | C10: 否 | D10: =VLOOKUP(A10,'OHT执行（30%）'!$A:$G,7,FALSE) -> 9.0426132 | E10: =VLOOKUP(A10,'保障-(10%)'!$A:$G,7,FALSE) -> 8.1259523 | F10: =IFERROR(VLOOKUP(A10,'影响力-(10%)'!$A$1:$E$55,5,FALSE),AVERAGE('影响力-(10%)'!$E$2:$E$55)) -> 10 | G10: =VLOOKUP(A10,'努力度(10%)'!$A$1:$C$62,3,FALSE) -> 9.74 | H10: =VLOOKUP(A10,'系统价值分（5%）'!A:D,4,FALSE) -> 9.49 | I10: =(0.3*D10+0.1*E10+0.1*F10+0.1*G10+H10*0.05)/0.65 -> 9.1905834 | J10: =COUNTIF(I:I,">"&I10)+1 -> 9 | K10: =VLOOKUP(A10,$R:$T,3,FALSE()) -> RD | O10: 郭亚奎 | R10: 王瑞娟 | S10: 学科工具 | T10: QA
A11: 谷继显 | B11: =VLOOKUP(A11,R:S,2,FALSE) -> 学科工具 | C11: 是 | D11: =VLOOKUP(A11,'OHT执行（30%）'!$A:$G,7,FALSE) -> 8.9094506 | E11: =VLOOKUP(A11,'保障-(10%)'!$A:$G,7,FALSE) -> 7.9017308 | F11: =IFERROR(VLOOKUP(A11,'影响力-(10%)'!$A$1:$E$55,5,FALSE),AVERAGE('影响力-(10%)'!$E$2:$E$55)) -> 10 | G11: =VLOOKUP(A11,'努力度(10%)'!$A$1:$C$62,3,FALSE) -> 10 | H11: =VLOOKUP(A11,'系统价值分（5%）'!A:D,4,FALSE) -> 10 | I11: =(0.3*D11+0.1*E11+0.1*F11+0.1*G11+H11*0.05)/0.65 -> 9.1738589 | J11: =COUNTIF(I:I,">"&I11)+1 -> 10 | K11: =VLOOKUP(A11,$R:$T,3,FALSE()) -> RD | O11: 许诺 | R11: 程振国 | S11: 站内营销 | T11: FE
A12: 雷朝军 | B12: =VLOOKUP(A12,R:S,2,FALSE) -> 学员旅程 | C12: 否 | D12: =VLOOKUP(A12,'OHT执行（30%）'!$A:$G,7,FALSE) -> 9.1354792 | E12: =VLOOKUP(A12,'保障-(10%)'!$A:$G,7,FALSE) -> 8.2 | F12: =IFERROR(VLOOKUP(A12,'影响力-(10%)'!$A$1:$E$55,5,FALSE),AVERAGE('影响力-(10%)'!$E$2:$E$55)) -> 10 | G12: =VLOOKUP(A12,'努力度(10%)'!$A$1:$C$62,3,FALSE) -> 9.82 | H12: =VLOOKUP(A12,'系统价值分（5%）'!A:D,4,FALSE) -> 8 | I12: =(0.3*D12+0.1*E12+0.1*F12+0.1*G12+H12*0.05)/0.65 -> 9.1425289 | J12: =COUNTIF(I:I,">"&I12)+1 -> 11 | K12: =VLOOKUP(A12,$R:$T,3,FALSE()) -> FE | O12: 朱艳梅 | R12: 王平 | S12: 站内营销 | T12: QA
A13: 刘志伟 | B13: =VLOOKUP(A13,R:S,2,FALSE) -> 三方能力 | C13: 否 | D13: =VLOOKUP(A13,'OHT执行（30%）'!$A:$G,7,FALSE) -> 8.8328007 | E13: =VLOOKUP(A13,'保障-(10%)'!$A:$G,7,FALSE) -> 7.8335923 | F13: =IFERROR(VLOOKUP(A13,'影响力-(10%)'!$A$1:$E$55,5,FALSE),AVERAGE('影响力-(10%)'!$E$2:$E$55)) -> 10 | G13: =VLOOKUP(A13,'努力度(10%)'!$A$1:$C$62,3,FALSE) -> 9.36 | H13: =VLOOKUP(A13,'系统价值分（5%）'!A:D,4,FALSE) -> 10 | I13: =(0.3*D13+0.1*E13+0.1*F13+0.1*G13+H13*0.05)/0.65 -> 9.0295376 | J13: =COUNTIF(I:I,">"&I13)+1 -> 12 | K13: =VLOOKUP(A13,$R:$T,3,FALSE()) -> PM | O13: 赵学姣 | R13: 谷继显 | S13: 学科工具 | T13: RD
... A54: 李悦冰 | B54: =VLOOKUP(A54,R:S,2,FALSE) -> 学员旅程 | C54: 否 | D54: =VLOOKUP(A54,'OHT执行（30%）'!$A:$G,7,FALSE) -> 5.6059396 | E54: =VLOOKUP(A54,'保障-(10%)'!$A:$G,7,FALSE) -> 8.2 | F54: =IFERROR(VLOOKUP(A54,'影响力-(10%)'!$A$1:$E$55,5,FALSE),AVERAGE('影响力-(10%)'!$E$2:$E$55)) -> 10 | G54: =VLOOKUP(A54,'努力度(10%)'!$A$1:$C$62,3,FALSE) -> 9 | H54: =VLOOKUP(A54,'系统价值分（5%）'!A:D,4,FALSE) -> 8 | I54: =(0.3*D54+0.1*E54+0.1*F54+0.1*G54+H54*0.05)/0.65 -> 7.3873567 | J54: =COUNTIF(I:I,">"&I54)+1 -> 53 | K54: =VLOOKUP(A54,$R:$T,3,FALSE()) -> QA | O54: 王静 | R54: 唐志坚 | S54: 督导学 | T54: FE
A55: 王静 | B55: =VLOOKUP(A55,R:S,2,FALSE) -> 三方能力 | C55: 否 | D55: =VLOOKUP(A55,'OHT执行（30%）'!$A:$G,7,FALSE) -> 5.6059396 | E55: =VLOOKUP(A55,'保障-(10%)'!$A:$G,7,FALSE) -> 8.2 | F55: =IFERROR(VLOOKUP(A55,'影响力-(10%)'!$A$1:$E$55,5,FALSE),AVERAGE('影响力-(10%)'!$E$2:$E$55)) -> 10 | G55: =VLOOKUP(A55,'努力度(10%)'!$A$1:$C$63,3,FALSE) -> 9 | H55: =VLOOKUP(A55,'系统价值分（5%）'!A:D,4,FALSE) -> 8 | I55: =(0.3*D55+0.1*E55+0.1*F55+0.1*G55+H55*0.05)/0.65 -> 7.3873567 | J55: =COUNTIF(I:I,">"&I55)+1 -> 53 | K55: =VLOOKUP(A55,$R:$T,3,FALSE()) -> PM | O55: 陈佳莹 | R55: 赵丙圯 | S55: 学员旅程 | T55: QA
A56: 高亦非 | B56: =VLOOKUP(A56,R:S,2,FALSE) -> 站内营销 | C56: 否 | D56: =VLOOKUP(A56,'OHT执行（30%）'!$A:$G,7,FALSE) -> 5.6059396 | E56: =VLOOKUP(A56,'保障-(10%)'!$A:$G,7,FALSE) -> 8.2 | F56: =IFERROR(VLOOKUP(A56,'影响力-(10%)'!$A$1:$E$55,5,FALSE),AVERAGE('影响力-(10%)'!$E$2:$E$55)) -> 10 | G56: =VLOOKUP(A56,'努力度(10%)'!$A$1:$C$62,3,FALSE) -> 5.92 | H56: =VLOOKUP(A56,'系统价值分（5%）'!A:D,4,FALSE) -> 10 | I56: =(0.3*D56+0.1*E56+0.1*F56+0.1*G56+H56*0.05)/0.65 -> 7.0673567 | J56: =COUNTIF(I:I,">"&I56)+1 -> 55 | K56: =VLOOKUP(A56,$R:$T,3,FALSE()) -> FE | O56: 廖金 | R56: 杨爱学 | S56: 督导学 | T56: QA
A57: 廖金 | B57: =VLOOKUP(A57,R:S,2,FALSE) -> 三教服务 | C57: 否 | D57: =VLOOKUP(A57,'OHT执行（30%）'!$A:$G,7,FALSE) -> 5.605356 | E57: =VLOOKUP(A57,'保障-(10%)'!$A:$G,7,FALSE) -> 7.9984992 | F57: =IFERROR(VLOOKUP(A57,'影响力-(10%)'!$A$1:$E$55,5,FALSE),AVERAGE('影响力-(10%)'!$E$2:$E$55)) -> 10 | G57: =VLOOKUP(A57,'努力度(10%)'!$A$1:$C$62,3,FALSE) -> 5.24 | H57: =VLOOKUP(A57,'系统价值分（5%）'!A:D,4,FALSE) -> 8 | I57: =(0.3*D57+0.1*E57+0.1*F57+0.1*G57+H57*0.05)/0.65 -> 6.7776257 | J57: =COUNTIF(I:I,">"&I57)+1 -> 56 | K57: =VLOOKUP(A57,$R:$T,3,FALSE()) -> FE | O57: 肖傲 | R57: 李澜楷 | S57: 站台 | T57: PM

Sheet 数据透视表
A1: 车厢 | B1: 平均值:OHT执行30% | C1: 平均值:OHT保障10% | D1: 平均值:努力度10% | E1: 平均值:价值分5% | F1: 平均值:总分 | G1: 平均值:RANK
A2: 督导学 | B2: 7.9997047 | C2: 8.2532584 | D2: 8.9514286 | E2: 9.28 | F2: 8.591354 | G2: 23.285714
A3: 三方能力 | B3: 7.876832 | C3: 8.1970611 | D3: 8.9657143 | E3: 9.7142857 | F3: 8.5616022 | G3: 23.857143
A4: 三教服务 | B4: 7.7392783 | C4: 8.2775112 | D4: 8.4775 | E4: 8 | F4: 8.3035148 | G4: 31.375
A5: 学科工具 | B5: 8.3329486 | C5: 8.2560501 | D5: 9.864 | E5: 10 | F5: 8.9413686 | G5: 16
A6: 学员旅程 | B6: 6.887986 | C6: 7.6218545 | D6: 9.045 | E6: 8 | F6: 7.8970481 | G6: 43.083333
A7: 站内营销 | B7: 7.9313956 | C7: 8.3315629 | D7: 8.6890909 | E7: 10 | F7: 8.5868985 | G7: 23.909091
A8: 站台 | B8: 8.3672887 | C8: 8.1914848 | D8: 9.32 | E8: 8.256 | F8: 8.7294386 | G8: 19.6
A9: (空白)
A10: 总计 | B10: 7.7536791 | C10: 8.1221717 | D10: 8.9687273 | E10: 8.9861818 | F10: 8.4376965 | G10: 27.981818
A12: 归属实体 | B12: 平均值:OHT执行30% | C12: 平均值:OHT保障10% | D12: 平均值:努力度10% | E12: 平均值:价值分5% | F12: 平均值:总分 | G12: 平均值:RANK
A13: FE | B13: 7.5913412 | C13: 7.9116466 | D13: 8.7790476 | E13: 8.9447619 | F13: 8.2980152 | G13: 31.761905
A14: PM | B14: 7.9600787 | C14: 8.1505492 | D14: 8.842 | E14: 8.728 | F14: 8.497967 | G14: 26.7
A15: QA | B15: 7.5167218 | C15: 8.5776795 | D15: 8.8142857 | E15: 9.04 | F15: 8.3787893 | G15: 27.714286
A16: RD | B16: 7.9303735 | C16: 8.1779775 | D16: 9.3411765 | E16: 9.1670588 | F16: 8.5990467 | G16: 24.176471
A17: (空白)
A18: 总计 | B18: 7.7536791 | C18: 8.1221717 | D18: 8.9687273 | E18: 8.9861818 | F18: 8.4376965 | G18: 27.981818

Sheet OHT执行（30%）
A1: 姓名 | B1: 车厢得分 | C1: 站台得分 | D1: 车厢-分位 | E1: 站台-分位 | F1: 整体-分位 | G1: 十分制 | K1: 车厢 | L1: 站台
A2: 王丽萍 | B2: =IFERROR(VLOOKUP(A2,'OHT-车厢数据'!$A:$E,5,FALSE),0) -> 106.90802 | C2: =IFERROR(VLOOKUP(A2,'OHT-站台数据'!$A:$B,2,FALSE),0) -> 101.2 | D2: =IF(B2>K2,_xlfn.NORM.DIST(B2,K$2,K$4,TRUE),_xlfn.NORM.DIST(B2,K$2,K$5,TRUE)) -> 0.97756389 | E2: =IF(C2>L2,_xlfn.NORM.DIST(C2,L$2,L$4,TRUE),_xlfn.NORM.DIST(C2,L$2,L$5,TRUE)) -> 0.30096306 | F2: =MAX(D2,E2)*0.9+MIN(D2,E2)/5 -> 0.94000011 | G2: =(F2-0.1)*4+6 -> 9.3600005 | J2: 基准值 | K2: =K10 -> 75.39464 | L2: =L10 -> 122.5
A3: 茆伟 | B3: =IFERROR(VLOOKUP(A3,'OHT-车厢数据'!$A:$E,5,FALSE),0) -> 86.11455 | C3: =IFERROR(VLOOKUP(A3,'OHT-站台数据'!$A:$B,2,FALSE),0) -> 191.5 | D3: =IF(B3>K3,_xlfn.NORM.DIST(B3,K$2,K$4,TRUE),_xlfn.NORM.DIST(B3,K$2,K$5,TRUE)) -> 0.75248495 | E3: =IF(C3>L3,_xlfn.NORM.DIST(C3,L$2,L$4,TRUE),_xlfn.NORM.DIST(C3,L$2,L$5,TRUE)) -> 0.64225796 | F3: =MAX(D3,E3)*0.9+MIN(D3,E3)/5 -> 0.80568805 | G3: =(F3-0.1)*4+6 -> 8.8227522 | J3: 标准差 | K3: =STDEV(B:B) -> 33.394485 | L3: {=_xlfn.STDEV.S(IF(C:C>0,C:C))} -> 177.02133
A4: 谷继显 | B4: =IFERROR(VLOOKUP(A4,'OHT-车厢数据'!$A:$E,5,FALSE),0) -> 97.36331 | C4: =IFERROR(VLOOKUP(A4,'OHT-站台数据'!$A:$B,2,FALSE),0) -> 0 | D4: =IF(B4>K4,_xlfn.NORM.DIST(B4,K$2,K$4,TRUE),_xlfn.NORM.DIST(B4,K$2,K$5,TRUE)) -> 0.91899186 | E4: =IF(C4>L4,_xlfn.NORM.DIST(C4,L$2,L$4,TRUE),_xlfn.NORM.DIST(C4,L$2,L$5,TRUE)) -> 0.001349898 | F4: =MAX(D4,E4)*0.9+MIN(D4,E4)/5 -> 0.82736265 | G4: =(F4-0.1)*4+6 -> 8.9094506 | J4: 标准差-右侧 | K4: =(MAX(B:B)-K2)/3 -> 15.710733 | L4: =(MAX(C:C)-L2)/3 -> 189.3
A5: 吴锣钢 | B5: =IFERROR(VLOOKUP(A5,'OHT-车厢数据'!$A:$E,5,FALSE),0) -> 122.52684 | C5: =IFERROR(VLOOKUP(A5,'OHT-站台数据'!$A:$B,2,FALSE),0) -> 67.35 | D5: =IF(B5>K5,_xlfn.NORM.DIST(B5,K$2,K$4,TRUE),_xlfn.NORM.DIST(B5,K$2,K$5,TRUE)) -> 0.9986501 | E5: =IF(C5>L5,_xlfn.NORM.DIST(C5,L$2,L$4,TRUE),_xlfn.NORM.DIST(C5,L$2,L$5,TRUE)) -> 0.38539699 | F5: =MAX(D5,E5)*0.9+MIN(D5,E5)/5 -> 0.97586449 | G5: =(F5-0.1)*4+6 -> 9.503458 | J5: 标准差-左侧 | K5: =(K2)/3 -> 25.131547 | L5: =(L2)/3 -> 40.833333
A6: 李阔 | B6: =IFERROR(VLOOKUP(A6,'OHT-车厢数据'!$A:$E,5,FALSE),0) -> 111.28586 | C6: =IFERROR(VLOOKUP(A6,'OHT-站台数据'!$A:$B,2,FALSE),0) -> 0 | D6: =IF(B6>K6,_xlfn.NORM.DIST(B6,K$2,K$4,TRUE),_xlfn.NORM.DIST(B6,K$2,K$5,TRUE)) -> 0.98882901 | E6: =IF(C6>L6,_xlfn.NORM.DIST(C6,L$2,L$4,TRUE),_xlfn.NORM.DIST(C6,L$2,L$5,TRUE)) -> 0.001349898 | F6: =MAX(D6,E6)*0.9+MIN(D6,E6)/5 -> 0.89021609 | G6: =(F6-0.1)*4+6 -> 9.1608644
A7: 王秉庵 | B7: =IFERROR(VLOOKUP(A7,'OHT-车厢数据'!$A:$E,5,FALSE),0) -> 115.06578 | C7: =IFERROR(VLOOKUP(A7,'OHT-站台数据'!$A:$B,2,FALSE),0) -> 95.6 | D7: =IF(B7>K7,_xlfn.NORM.DIST(B7,K$2,K$4,TRUE),_xlfn.NORM.DIST(B7,K$2,K$5,TRUE)) -> 0.9942167 | E7: =IF(C7>L7,_xlfn.NORM.DIST(C7,L$2,L$4,TRUE),_xlfn.NORM.DIST(C7,L$2,L$5,TRUE)) -> 0.44349953 | F7: =MAX(D7,E7)*0.9+MIN(D7,E7)/5 -> 0.98349493 | G7: =(F7-0.1)*4+6 -> 9.5339797
A8: 张辰 | B8: =IFERROR(VLOOKUP(A8,'OHT-车厢数据'!$A:$E,5,FALSE),0) -> 2.73444 | C8: =IFERROR(VLOOKUP(A8,'OHT-站台数据'!$A:$B,2,FALSE),0) -> 362.45 | D8: =IF(B8>K8,_xlfn.NORM.DIST(B8,K$2,K$4,TRUE),_xlfn.NORM.DIST(B8,K$2,K$5,TRUE)) -> 0.0019189 | E8: =IF(C8>L8,_xlfn.NORM.DIST(C8,L$2,L$4,TRUE),_xlfn.NORM.DIST(C8,L$2,L$5,TRUE)) -> 0.89752328 | F8: =MAX(D8,E8)*0.9+MIN(D8,E8)/5 -> 0.80815473 | G8: =(F8-0.1)*4+6 -> 8.8326189 | J8: 不含为0的 | K8: =AVERAGEIF(B:B,">0",B:B) -> 69.881535 | L8: =AVERAGEIF(C:C,">0",C:C) -> 194.82293 | M8: 平均值
A9: 熊苓军 | B9: =IFERROR(VLOOKUP(A9,'OHT-车厢数据'!$A:$E,5,FALSE),0) -> 5.07973 | C9: =IFERROR(VLOOKUP(A9,'OHT-站台数据'!$A:$B,2,FALSE),0) -> 606.75 | D9: =IF(B9>K9,_xlfn.NORM.DIST(B9,K$2,K$4,TRUE),_xlfn.NORM.DIST(B9,K$2,K$5,TRUE)) -> 0.0025720059 | E9: =IF(C9>L9,_xlfn.NORM.DIST(C9,L$2,L$4,TRUE),_xlfn.NORM.DIST(C9,L$2,L$5,TRUE)) -> 0.99473784 | F9: =MAX(D9,E9)*0.9+MIN(D9,E9)/5 -> 0.89577846 | G9: =(F9-0.1)*4+6 -> 9.1831138 | K9: =MAX(B:B)/2 -> 61.26342 | L9: =MAX(C:C)/2 -> 345.2 | M9: 最大值/2
A10: 刘宇祥 | B10: =IFERROR(VLOOKUP(A10,'OHT-车厢数据'!$A:$E,5,FALSE),0) -> 63.24248 | C10: =IFERROR(VLOOKUP(A10,'OHT-站台数据'!$A:$B,2,FALSE),0) -> 0 | D10: =IF(B10>K10,_xlfn.NORM.DIST(B10,K$2,K$4,TRUE),_xlfn.NORM.DIST(B10,K$2,K$5,TRUE)) -> 0.31435545 | E10: =IF(C10>L10,_xlfn.NORM.DIST(C10,L$2,L$4,TRUE),_xlfn.NORM.DIST(C10,L$2,L$5,TRUE)) -> 0.001349898 | F10: =MAX(D10,E10)*0.9+MIN(D10,E10)/5 -> 0.28318988 | G10: =(F10-0.1)*4+6 -> 6.7327595 | K10: {=_xlfn.AGGREGATE(15,6,B:B/(B:B>0),(COUNTIF(B:B,">0")+1)/2)} -> 75.39464 | L10: {=_xlfn.AGGREGATE(15,6,C:C/(C:C>0),(COUNTIF(C:C,">0")+1)/2)} -> 122.5 | M10: 中位数
A11: 郭相磊 | B11: =IFERROR(VLOOKUP(A11,'OHT-车厢数据'!$A:$E,5,FALSE),0) -> 91.96681 | C11: =IFERROR(VLOOKUP(A11,'OHT-站台数据'!$A:$B,2,FALSE),0) -> 0 | D11: =IF(B11>K11,_xlfn.NORM.DIST(B11,K$2,K$4,TRUE),_xlfn.NORM.DIST(B11,K$2,K$5,TRUE)) -> 0.85424871 | E11: =IF(C11>L11,_xlfn.NORM.DIST(C11,L$2,L$4,TRUE),_xlfn.NORM.DIST(C11,L$2,L$5,TRUE)) -> 0.001349898 | F11: =MAX(D11,E11)*0.9+MIN(D11,E11)/5 -> 0.76909382 | G11: =(F11-0.1)*4+6 -> 8.6763753
A12: 郭亚奎 | B12: =IFERROR(VLOOKUP(A12,'OHT-车厢数据'!$A:$E,5,FALSE),0) -> 2.73444 | C12: =IFERROR(VLOOKUP(A12,'OHT-站台数据'!$A:$B,2,FALSE),0) -> 690.4 | D12: =IF(B12>K12,_xlfn.NORM.DIST(B12,K$2,K$4,TRUE),_xlfn.NORM.DIST(B12,K$2,K$5,TRUE)) -> 1.8741091e-06 | E12: =IF(C12>L12,_xlfn.NORM.DIST(C12,L$2,L$4,TRUE),_xlfn.NORM.DIST(C12,L$2,L$5,TRUE)) -> 0.9986501 | F12: =MAX(D12,E12)*0.9+MIN(D12,E12)/5 -> 0.89878547 | G12: =(F12-0.1)*4+6 -> 9.1951419
A13: 李明 | B13: =IFERROR(VLOOKUP(A13,'OHT-车厢数据'!$A:$E,5,FALSE),0) -> 99.94721 | C13: =IFERROR(VLOOKUP(A13,'OHT-站台数据'!$A:$B,2,FALSE),0) -> 0 | D13: =IF(B13>K13,_xlfn.NORM.DIST(B13,K$2,K$4,TRUE),_xlfn.NORM.DIST(B13,K$2,K$5,TRUE)) -> 0.94094895 | E13: =IF(C13>L13,_xlfn.NORM.DIST(C13,L$2,L$4,TRUE),_xlfn.NORM.DIST(C13,L$2,L$5,TRUE)) -> 0.001349898 | F13: =MAX(D13,E13)*0.9+MIN(D13,E13)/5 -> 0.84712403 | G13: =(F13-0.1)*4+6 -> 8.9884961
A14: 任广琪 | B14: =IFERROR(VLOOKUP(A14,'OHT-车厢数据'!$A:$E,5,FALSE),0) -> 75.39464 | C14: =IFERROR(VLOOKUP(A14,'OHT-站台数据'!$A:$B,2,FALSE),0) -> 0 | D14: =IF(B14>K14,_xlfn.NORM.DIST(B14,K$2,K$4,TRUE),_xlfn.NORM.DIST(B14,K$2,K$5,TRUE)) -> 0.5 | E14: =IF(C14>L14,_xlfn.NORM.DIST(C14,L$2,L$4,TRUE),_xlfn.NORM.DIST(C14,L$2,L$5,TRUE)) -> 0.001349898 | F14: =MAX(D14,E14)*0.9+MIN(D14,E14)/5 -> 0.45026998 | G14: =(F14-0.1)*4+6 -> 7.4010799
A15: 张雷雷 | B15: =IFERROR(VLOOKUP(A15,'OHT-车厢数据'!$A:$E,5,FALSE),0) -> 98.46881 | C15: =IFERROR(VLOOKUP(A15,'OHT-站台数据'!$A:$B,2,FALSE),0) -> 0 | D15: =IF(B15>K15,_xlfn.NORM.DIST(B15,K$2,K$4,TRUE),_xlfn.NORM.DIST(B15,K$2,K$5,TRUE)) -> 0.92904132 | E15: =IF(C15>L15,_xlfn.NORM.DIST(C15,L$2,L$4,TRUE),_xlfn.NORM.DIST(C15,L$2,L$5,TRUE)) -> 0.001349898 | F15: =MAX(D15,E15)*0.9+MIN(D15,E15)/5 -> 0.83640717 | G15: =(F15-0.1)*4+6 -> 8.9456287
A16: 刘玉录 | B16: =IFERROR(VLOOKUP(A16,'OHT-车厢数据'!$A:$E,5,FALSE),0) -> 81.67547 | C16: =IFERROR(VLOOKUP(A16,'OHT-站台数据'!$A:$B,2,FALSE),0) -> 0 | D16: =IF(B16>K16,_xlfn.NORM.DIST(B16,K$2,K$4,TRUE),_xlfn.NORM.DIST(B16,K$2,K$5,TRUE)) -> 0.65534056 | E16: =IF(C16>L16,_xlfn.NORM.DIST(C16,L$2,L$4,TRUE),_xlfn.NORM.DIST(C16,L$2,L$5,TRUE)) -> 0.001349898 | F16: =MAX(D16,E16)*0.9+MIN(D16,E16)/5 -> 0.59007648 | G16: =(F16-0.1)*4+6 -> 7.9603059
A17: 刘志伟 | B17: =IFERROR(VLOOKUP(A17,'OHT-车厢数据'!$A:$E,5,FALSE),0) -> 95.32458 | C17: =IFERROR(VLOOKUP(A17,'OHT-站台数据'!$A:$B,2,FALSE),0) -> 0 | D17: =IF(B17>K17,_xlfn.NORM.DIST(B17,K$2,K$4,TRUE),_xlfn.NORM.DIST(B17,K$2,K$5,TRUE)) -> 0.89770021 | E17: =IF(C17>L17,_xlfn.NORM.DIST(C17,L$2,L$4,TRUE),_xlfn.NORM.DIST(C17,L$2,L$5,TRUE)) -> 0.001349898 | F17: =MAX(D17,E17)*0.9+MIN(D17,E17)/5 -> 0.80820017 | G17: =(F17-0.1)*4+6 -> 8.8328007
A18: 刘昊恺 | B18: =IFERROR(VLOOKUP(A18,'OHT-车厢数据'!$A:$E,5,FALSE),0) -> 99.53964 | C18: =IFERROR(VLOOKUP(A18,'OHT-站台数据'!$A:$B,2,FALSE),0) -> 0 | D18: =IF(B18>K18,_xlfn.NORM.DIST(B18,K$2,K$4,TRUE),_xlfn.NORM.DIST(B18,K$2,K$5,TRUE)) -> 0.93783466 | E18: =IF(C18>L18,_xlfn.NORM.DIST(C18,L$2,L$4,TRUE),_xlfn.NORM.DIST(C18,L$2,L$5,TRUE)) -> 0.001349898 | F18: =MAX(D18,E18)*0.9+MIN(D18,E18)/5 -> 0.84432117 | G18: =(F18-0.1)*4+6 -> 8.9772847
A19: 朱静娜 | B19: =IFERROR(VLOOKUP(A19,'OHT-车厢数据'!$A:$E,5,FALSE),0) -> 97.42883 | C19: =IFERROR(VLOOKUP(A19,'OHT-站台数据'!$A:$B,2,FALSE),0) -> 0 | D19: =IF(B19>K19,_xlfn.NORM.DIST(B19,K$2,K$4,TRUE),_xlfn.NORM.DIST(B19,K$2,K$5,TRUE)) -> 0.91961593 | E19: =IF(C19>L19,_xlfn.NORM.DIST(C19,L$2,L$4,TRUE),_xlfn.NORM.DIST(C19,L$2,L$5,TRUE)) -> 0.001349898 | F19: =MAX(D19,E19)*0.9+MIN(D19,E19)/5 -> 0.82792431 | G19: =(F19-0.1)*4+6 -> 8.9116973
A20: 朱艳梅 | B20: =IFERROR(VLOOKUP(A20,'OHT-车厢数据'!$A:$E,5,FALSE),0) -> 85.85038 | C20: =IFERROR(VLOOKUP(A20,'OHT-站台数据'!$A:$B,2,FALSE),0) -> 133.2 | D20: =IF(B20>K20,_xlfn.NORM.DIST(B20,K$2,K$4,TRUE),_xlfn.NORM.DIST(B20,K$2,K$5,TRUE)) -> 0.74713965 | E20: =IF(C20>L20,_xlfn.NORM.DIST(C20,L$2,L$4,TRUE),_xlfn.NORM.DIST(C20,L$2,L$5,TRUE)) -> 0.52253783 | F20: =MAX(D20,E20)*0.9+MIN(D20,E20)/5 -> 0.77693325 | G20: =(F20-0.1)*4+6 -> 8.707733
A21: 丁星杰 | B21: =IFERROR(VLOOKUP(A21,'OHT-车厢数据'!$A:$E,5,FALSE),0) -> 85.19738 | C21: =IFERROR(VLOOKUP(A21,'OHT-站台数据'!$A:$B,2,FALSE),0) -> 152.925 | D21: =IF(B21>K21,_xlfn.NORM.DIST(B21,K$2,K$4,TRUE),_xlfn.NORM.DIST(B21,K$2,K$5,TRUE)) -> 0.73367037 | E21: =IF(C21>L21,_xlfn.NORM.DIST(C21,L$2,L$4,TRUE),_xlfn.NORM.DIST(C21,L$2,L$5,TRUE)) -> 0.5638445 | F21: =MAX(D21,E21)*0.9+MIN(D21,E21)/5 -> 0.77307223 | G21: =(F21-0.1)*4+6 -> 8.6922889
A22: 许诺 | B22: =IFERROR(VLOOKUP(A22,'OHT-车厢数据'!$A:$E,5,FALSE),0) -> 75.74771 | C22: =IFERROR(VLOOKUP(A22,'OHT-站台数据'!$A:$B,2,FALSE),0) -> 0 | D22: =IF(B22>K22,_xlfn.NORM.DIST(B22,K$2,K$4,TRUE),_xlfn.NORM.DIST(B22,K$2,K$5,TRUE)) -> 0.50896474 | E22: =IF(C22>L22,_xlfn.NORM.DIST(C22,L$2,L$4,TRUE),_xlfn.NORM.DIST(C22,L$2,L$5,TRUE)) -> 0.001349898 | F22: =MAX(D22,E22)*0.9+MIN(D22,E22)/5 -> 0.45833825 | G22: =(F22-0.1)*4+6 -> 7.433353
... A57: 唐志坚 | B57: =IFERROR(VLOOKUP(A57,'OHT-车厢数据'!$A:$E,5,FALSE),0) -> 9.09573 | C57: =IFERROR(VLOOKUP(A57,'OHT-站台数据'!$A:$B,2,FALSE),0) -> 86.2 | D57: =IF(B57>K57,_xlfn.NORM.DIST(B57,K$2,K$4,TRUE),_xlfn.NORM.DIST(B57,K$2,K$5,TRUE)) -> 1.2216443e-05 | E57: =IF(C57>L57,_xlfn.NORM.DIST(C57,L$2,L$4,TRUE),_xlfn.NORM.DIST(C57,L$2,L$5,TRUE)) -> 0.42396545 | F57: =MAX(D57,E57)*0.9+MIN(D57,E57)/5 -> 0.38157135 | G57: =(F57-0.1)*4+6 -> 7.1262854

Sheet OHT-车厢数据
A1: 姓名 | B1: 车厢 | C1: 得分 | D1: BO加分 | E1: 总分 | L1: 车厢12月份数据 | T1: 车厢截止1月份数据
A2: 王丽萍 | B2: 督导学服务-FC | C2: =IFERROR(VLOOKUP(A2,$T:$Y,6,0), 0) -> 106.90802 | D2: 0 | E2: =SUM(C2:D2) -> 106.90802 | L2: name | M2: fc | N2: SUM(Bci) | O2: SUM(Bpi) | P2: SUM(Bmi) | Q2: SUM(B2) | T2: name | U2: fc | V2: SUM(Bci) | W2: SUM(Bpi) | X2: SUM(Bmi) | Y2: SUM(B2)
A3: 李阔 | B3: 站内营销-FC | C3: =IFERROR(VLOOKUP(A3,$T:$Y,6,0), 0) -> 84.91586 | D3: 26.37 | E3: =SUM(C3:D3) -> 111.28586 | L3: 吴锣钢 | M3: 学员全旅程服务-FC | N3: 6.02341 | O3: 49.87121 | P3: 0 | Q3: 55.89462 | T3: 吴锣钢 | U3: 学员全旅程服务-FC | V3: 14.64789 | W3: 107.87895 | X3: 0 | Y3: 122.52684
A4: 吴锣钢 | B4: 学员全旅程服务-FC | C4: =IFERROR(VLOOKUP(A4,$T:$Y,6,0), 0) -> 122.52684 | D4: 0 | E4: =SUM(C4:D4) -> 122.52684 | L4: 王秉庵 | M4: 学科工具-FC | N4: 7.98836 | O4: 40.91727 | P4: 6.85374 | Q4: 55.75937 | T4: 王秉庵 | U4: 学科工具-FC | V4: 15.09246 | W4: 85.78245 | X4: 14.19087 | Y4: 115.06578
A5: 刘宇祥 | B5: 教学教研教务-FC | C5: =IFERROR(VLOOKUP(A5,$T:$Y,6,0), 0) -> 63.24248 | D5: 0 | E5: =SUM(C5:D5) -> 63.24248 | L5: 李明 | M5: 站内营销-FC | N5: 7.51678 | O5: 36.37216 | P5: 6.72051 | Q5: 50.60945 | T5: 王丽萍 | U5: 督导学服务-FC | V5: 9.09573 | W5: 85.19455 | X5: 12.61774 | Y5: 106.90802
A6: 谷继显 | B6: 学科工具-FC | C6: =IFERROR(VLOOKUP(A6,$T:$Y,6,0), 0) -> 97.36331 | D6: 0 | E6: =SUM(C6:D6) -> 97.36331 | L6: 王瑞娟 | M6: 学科工具-FC | N6: 7.90128 | O6: 36.68705 | P6: 5.29457 | Q6: 49.8829 | T6: 陈士卿 | U6: 三方能力对接-FC | V6: 15.69495 | W6: 74.00559 | X6: 15.66028 | Y6: 105.36082
A7: 李明 | B7: 站内营销-FC | C7: =IFERROR(VLOOKUP(A7,$T:$Y,6,0), 0) -> 99.94721 | D7: 0 | E7: =SUM(C7:D7) -> 99.94721 | L7: 陈士卿 | M7: 三方能力对接-FC | N7: 7.34955 | O7: 35.7882 | P7: 6.46136 | Q7: 49.59911 | T7: 李明 | U7: 站内营销-FC | V7: 16.18364 | W7: 67.32455 | X7: 16.43902 | Y7: 99.94721
A8: 任广琪 | B8: 教学教研教务-FC | C8: =IFERROR(VLOOKUP(A8,$T:$Y,6,0), 0) -> 75.39464 | D8: 0 | E8: =SUM(C8:D8) -> 75.39464 | L8: 王丽萍 | M8: 督导学服务-FC | N8: 5.39186 | O8: 36.54256 | P8: 5.78785 | Q8: 47.72227 | T8: 刘昊恺 | U8: 站内营销-FC | V8: 16.35914 | W8: 69.49101 | X8: 13.68949 | Y8: 99.53964
A9: 王秉庵 | B9: 学科工具-FC | C9: =IFERROR(VLOOKUP(A9,$T:$Y,6,0), 0) -> 115.06578 | D9: 0 | E9: =SUM(C9:D9) -> 115.06578 | L9: 谷继显 | M9: 学科工具-FC | N9: 7.89778 | O9: 32.73811 | P9: 6.67117 | Q9: 47.30706 | T9: 张雷雷 | U9: 教学教研教务-FC | V9: 13.37634 | W9: 80.31478 | X9: 4.77769 | Y9: 98.46881
A10: 刘昊恺 | B10: 站内营销-FC | C10: =IFERROR(VLOOKUP(A10,$T:$Y,6,0), 0) -> 99.53964 | D10: 0 | E10: =SUM(C10:D10) -> 99.53964 | L10: 张雷雷 | M10: 教学教研教务-FC | N10: 6.70434 | O10: 37.05569 | P10: 2.63556 | Q10: 46.39559 | T10: 朱静娜 | U10: 站内营销-FC | V10: 16.02581 | W10: 76.11801 | X10: 5.28501 | Y10: 97.42883
A11: 朱静娜 | B11: 站内营销-FC | C11: =IFERROR(VLOOKUP(A11,$T:$Y,6,0), 0) -> 97.42883 | D11: 0 | E11: =SUM(C11:D11) -> 97.42883 | L11: 王英杰 | M11: 教学教研教务-FC | N11: 6.70434 | O11: 35.14027 | P11: 4.342 | Q11: 46.18661 | T11: 谷继显 | U11: 学科工具-FC | V11: 15.00188 | W11: 66.84881 | X11: 15.51262 | Y11: 97.36331
A12: 茆伟 | B12: 三方能力对接-FC | C12: =IFERROR(VLOOKUP(A12,$T:$Y,6,0), 0) -> 86.11455 | D12: 0 | E12: =SUM(C12:D12) -> 86.11455 | L12: 朱艳梅 | M12: 教学教研教务-FC | N12: 6.70434 | O12: 31.14367 | P12: 7.82085 | Q12: 45.66886 | T12: 刘志伟 | U12: 三方能力对接-FC | V12: 15.69495 | W12: 79.62963 | X12: 0 | Y12: 95.32458
A13: 张雷雷 | B13: 教学教研教务-FC | C13: =IFERROR(VLOOKUP(A13,$T:$Y,6,0), 0) -> 98.46881 | D13: 0 | E13: =SUM(C13:D13) -> 98.46881 | L13: 刘昊恺 | M13: 站内营销-FC | N13: 7.67632 | O13: 30.574 | P13: 7.18558 | Q13: 45.4359 | T13: 王英杰 | U13: 教学教研教务-FC | V13: 13.37634 | W13: 67.80493 | X13: 13.02557 | Y13: 94.20684
A14: 郭相磊 | B14: 学员全旅程服务-FC | C14: =IFERROR(VLOOKUP(A14,$T:$Y,6,0), 0) -> 91.96681 | D14: 0 | E14: =SUM(C14:D14) -> 91.96681 | L14: 朱静娜 | M14: 站内营销-FC | N14: 7.37329 | O14: 35.30171 | P14: 2.6391 | Q14: 45.3141 | T14: 郭相磊 | U14: 学员全旅程服务-FC | V14: 14.64789 | W14: 66.16284 | X14: 11.15608 | Y14: 91.96681
... A56: 唐志坚 | B56: 督导学服务-FC | C56: =IFERROR(VLOOKUP(A56,$T:$Y,6,0), 0) -> 9.09573 | D56: 0 | E56: =SUM(C56:D56) -> 9.09573 | L56: 王宁 | M56: 站台 | N56: 1.9525 | O56: 0 | P56: 0 | Q56: 1.9525 | T56: 郭亚奎 | U56: 站台 | V56: 2.73444 | W56: 0 | X56: 0 | Y56: 2.73444
L57: 郭亚奎 | M57: 站台 | N57: 1.9525 | O57: 0 | P57: 0 | Q57: 1.9525 | T57: 王宁 | U57: 站台 | V57: 2.73444 | W57: 0 | X57: 0 | Y57: 2.73444
L58: 熊苓军 | M58: 站台 | N58: 1.9525 | O58: 0 | P58: 0 | Q58: 1.9525 | T58: 刘红娇 | U58: 站台 | V58: 2.73444 | W58: 0 | X58: 0 | Y58: 2.73444

Sheet OHT-站台数据
A1: person | B1: 总积分 | U1: 12月份数据 | AB1: 截止1月份数据
A2: 陈士卿 | B2: 122.5 | U2: person | V2: person_type | W2: 总积分 | X2: 单需求平均积分 | Y2: 实际总工时 | AB2: 人员 | AC2: 积分
A3: 丁星杰 | B3: 152.925 | U3: 郭亚奎 | V3: 全职飞行员 | W3: 384.2 | X3: 64.03 | Y3: 190 | AB3: 陈士卿 | AC3: 122.5
A4: 高彦超 | B4: 130.2 | U4: 熊苓军 | V4: 全职飞行员 | W4: 324.4 | X4: 54.07 | Y4: 159 | AB4: 丁星杰 | AC4: 152.925
A5: 郭梁 | B5: 60 | U5: 张辰 | V5: 全职飞行员 | W5: 236.7 | X5: 29.59 | Y5: 20 | AB5: 高彦超 | AC5: 130.2
A6: 郭亚奎 | B6: 690.4 | U6: 陈士卿 | V6: 临时飞行员 | W6: 187.7 | X6: 62.57 | Y6: 19 | AB6: 郭梁 | AC6: 60
A7: 雷朝军 | B7: 519.35 | U7: 茆伟 | V7: 临时飞行员 | W7: 146.25 | X7: 73.13 | Y7: 36 | AB7: 郭亚奎 | AC7: 690.4
A8: 李殿龙 | B8: 103.85 | U8: 朱艳梅 | V8: 临时飞行员 | W8: 133.2 | X8: 33.3 | Y8: 13 | AB8: 雷朝军 | AC8: 519.35
A9: 李红苗 | B9: 69.75 | U9: 王瑞娟 | V9: 临时飞行员 | W9: 130.8 | X9: 65.4 | Y9: 53 | AB9: 李殿龙 | AC9: 103.85
A10: 李澜楷 | B10: 146.44 | U10: 郭梁 | V10: 临时飞行员 | W10: 117 | X10: 58.5 | Y10: 1 | AB10: 李红苗 | AC10: 69.75
A11: 李盼盼 | B11: 342.15 | U11: 雷朝军 | V11: 临时飞行员 | W11: 95 | X11: 47.5 | Y11: 53 | AB11: 李澜楷 | AC11: 146.44
A12: 李思涵 | B12: 62.35 | U12: 钊文磊 | V12: 临时飞行员 | W12: 78 | X12: 78 | Y12: 15 | AB12: 李盼盼 | AC12: 342.15
A13: 李越 | B13: 27.05 | U13: 高彦超 | V13: 临时飞行员 | W13: 77.4 | X13: 77.4 | Y13: 44 | AB13: 李思涵 | AC13: 62.35
A14: 李占旭 | B14: 446 | U14: 王秉庵 | V14: 临时飞行员 | W14: 77 | X14: 77 | Y14: 26 | AB14: 李越 | AC14: 27.05
... A26: 杨爱学 | B26: 86.25 | U26: 杨爱学 | V26: 临时飞行员 | W26: 17.25 | X26: 17.25 | Y26: 0 | AB26: 熊苓军 | AC26: 606.75
A27: 袁荣 | B27: 12 | AB27: 杨爱学 | AC27: 86.25
A28: 张辰 | B28: 362.45 | AB28: 袁荣 | AC28: 12
A29: 钊文磊 | B29: 78 | AB29: 张辰 | AC29: 362.45
A30: 赵丙圯 | B30: 65.8 | AB30: 钊文磊 | AC30: 78
A31: 朱艳梅 | B31: 133.2 | AB31: 赵丙圯 | AC31: 65.8
AB32: 朱艳梅 | AC32: 133.2

Sheet 保障-(10%)
A1: 姓名 | B1: 线上故障(40%) | C1: 线上BUG(20%) | D1: 技术工单(20%) | E1: 漏洞超期(10%) | F1: 系统两用分(10%) | G1: 总分
A2: 李红苗 | B2: 10 | C2: 10 | D2: 8.0217824 | E2: 10 | F2: 0 | G2: 8.6043565
A3: 李思涵 | B3: 10 | C3: 10 | D3: 4.992496 | E3: 10 | F3: 4 | G3: 8.3984992
A4: 陈士卿 | B4: 10 | C4: 10 | D4: 6.4802541 | E4: 10 | F4: 0 | G4: 8.2960508
A5: 刘昊恺 | B5: 10 | C5: 10 | D5: 6.1426608 | E5: 10 | F5: 0 | G5: 8.2285322
A6: 朱艳梅 | B6: 10 | C6: 10 | D6: 7.390563 | E6: 10 | F6: 0 | G6: 8.4781126
A7: 陈忠勇 | B7: 10 | C7: 10 | D7: 5.0377897 | E7: 10 | F7: 0 | G7: 8.0075579
A8: 王平 | B8: 10 | C8: 10 | D8: 7.0970561 | E8: 10 | F8: 0 | G8: 8.4194112
A9: 王秉庵 | B9: 10 | C9: 10 | D9: 8.8940363 | E9: 10 | F9: 0 | G9: 8.7788073
A10: 朱静娜 | B10: 10 | C10: 10 | D10: 6.7708706 | E10: 10 | F10: 0 | G10: 8.3541741
A11: 赵学姣 | B11: 10 | C11: 10 | D11: 5.5748563 | E11: 10 | F11: 0 | G11: 8.1149713
A12: 王瑞娟 | B12: 10 | C12: 10 | D12: 5.777153 | E12: 10 | F12: 0 | G12: 8.1554306
A13: 丁星杰 | B13: 10 | C13: 10 | D13: 5.2124285 | E13: 10 | F13: 0 | G13: 8.0424857
... A57: 唐志坚 | B57: 10 | C57: 10 | D57: 5.1948476 | E57: 10 | F57: 0 | G57: 8.0389695

Sheet 影响力-(10%)
A1: 姓名 | B1: 自评 | C1: 同事 | D1: 他评 | E1: 得分
A2: 李殿龙 | B2: 5 | C2: 5 | D2: 5 | E2: =D2*2 -> 10 | G2: std | H2: =STDEV(D:D) -> 0
A3: 李向月 | B3: 5 | C3: 5 | D3: 5 | E3: =D3*2 -> 10 | G3: ave | H3: =AVERAGE(D:D) -> 5
A4: 王晨 | B4: 5 | C4: 5 | D4: 5 | E4: =D4*2 -> 10
A5: 王英杰 | B5: 5 | C5: 5 | D5: 5 | E5: =D5*2 -> 10
A6: 刘宇祥 | B6: 5 | C6: 5 | D6: 5 | E6: =D6*2 -> 10
A7: 文翰 | B7: 5 | C7: 5 | D7: 5 | E7: =D7*2 -> 10
A8: 雷朝军 | B8: 5 | C8: 5 | D8: 5 | E8: =D8*2 -> 10
A9: 李越 | B9: 5 | C9: 5 | D9: 5 | E9: =D9*2 -> 10
A10: 李悦冰 | B10: 5 | C10: 5 | D10: 5 | E10: =D10*2 -> 10
A11: 郭梁 | B11: 5 | C11: 5 | D11: 5 | E11: =D11*2 -> 10
A12: 钊文磊 | B12: 5 | C12: 5 | D12: 5 | E12: =D12*2 -> 10
A13: 李思涵 | B13: 5 | C13: 5 | D13: 5 | E13: =D13*2 -> 10
A14: 李祥勇 | B14: 5 | C14: 5 | D14: 5 | E14: =D14*2 -> 10
A15: 陈佳莹 | B15: 5 | C15: 5 | D15: 5 | E15: =D15*2 -> 10
... A55: 陈英杰 | B55: 5 | C55: 5 | D55: 5 | E55: =D55*2 -> 10

Sheet 努力度(10%)
A1: 姓名 | B1: 平均工时 | C1: 连续得分 | G1: 12月数据 | L1: 截止1月数据
A2: 袁荣 | B2: 12.66 | C2: =MIN((B2-10)*2+7,10) -> 10 | G2: 姓名 | H2: 平均工时 | I2: 连续得分 | L2: 姓名 | M2: 平均工时
A3: 王宁 | B3: 12.55 | C3: =MIN((B3-10)*2+7,10) -> 10 | G3: 陈忠勇 | H3: 12.41 | I3: =MIN((H3-10)*2+7,10) -> 10 | L3: 袁荣 | M3: 12.66
A4: 赵学姣 | B4: 12.4 | C4: =MIN((B4-10)*2+7,10) -> 10 | G4: 张培进 | H4: 12.26 | I4: =MIN((H4-10)*2+7,10) -> 10 | L4: 王宁 | M4: 12.55
A5: 陈忠勇 | B5: 12.32 | C5: =MIN((B5-10)*2+7,10) -> 10 | G5: 王宁 | H5: 12.1 | I5: =MIN((H5-10)*2+7,10) -> 10 | L5: 赵学姣 | M5: 12.4
A6: 谷继显 | B6: 12.29 | C6: =MIN((B6-10)*2+7,10) -> 10 | G6: 赵学姣 | H6: 12.05 | I6: =MIN((H6-10)*2+7,10) -> 10 | L6: 陈忠勇 | M6: 12.32
A7: 张培进 | B7: 12.27 | C7: =MIN((B7-10)*2+7,10) -> 10 | G7: 李越 | H7: 12 | I7: =MIN((H7-10)*2+7,10) -> 10 | L7: 谷继显 | M7: 12.29
A8: 王伊庆 | B8: 11.99 | C8: =MIN((B8-10)*2+7,10) -> 10 | G8: 王伊庆 | H8: 11.95 | I8: =MIN((H8-10)*2+7,10) -> 10 | L8: 张培进 | M8: 12.27
A9: 陈英杰 | B9: 11.79 | C9: =MIN((B9-10)*2+7,10) -> 10 | G9: 谷继显 | H9: 11.83 | I9: =MIN((H9-10)*2+7,10) -> 10 | L9: 王伊庆 | M9: 11.99
A10: 熊苓军 | B10: 11.78 | C10: =MIN((B10-10)*2+7,10) -> 10 | G10: 王瑞娟 | H10: 11.77 | I10: =MIN((H10-10)*2+7,10) -> 10 | L10: 陈英杰 | M10: 11.79
A11: 刘红娇 | B11: 11.78 | C11: =MIN((B11-10)*2+7,10) -> 10 | G11: 刘红娇 | H11: 11.69 | I11: =MIN((H11-10)*2+7,10) -> 10 | L11: 熊苓军 | M11: 11.78
A12: 刘昊恺 | B12: 11.76 | C12: =MIN((B12-10)*2+7,10) -> 10 | G12: 王平 | H12: 11.6 | I12: =MIN((H12-10)*2+7,10) -> 10 | L12: 刘红娇 | M12: 11.78
A13: 王秉庵 | B13: 11.72 | C13: =MIN((B13-10)*2+7,10) -> 10 | G13: 刘昊恺 | H13: 11.6 | I13: =MIN((H13-10)*2+7,10) -> 10 | L13: 刘昊恺 | M13: 11.76
A14: 王英杰 | B14: 11.7 | C14: =MIN((B14-10)*2+7,10) -> 10 | G14: 王英杰 | H14: 11.59 | I14: =MIN((H14-10)*2+7,10) -> 10 | L14: 王秉庵 | M14: 11.72
... A61: 廖金 | B61: 9.12 | C61: =MIN((B61-10)*2+7,10) -> 5.24 | G61: 赵江涛 | H61: 9.39 | I61: =MIN((H61-10)*2+7,10) -> 5.78 | L61: 赵江涛 | M61: 9.37
A62: 李悦冰 | B62: 11 | C62: =MIN((B62-10)*2+7,10) -> 9 | E62: 平均值 | G62: 廖金 | H62: 9.11 | I62: =MIN((H62-10)*2+7,10) -> 5.22 | L62: 廖金 | M62: 9.12
A63: 王静 | B63: 11 | C63: =MIN((B63-10)*2+7,10) -> 9 | E63: 平均值 | G63: 李悦冰 | H63: 11 | I63: =MIN((H63-10)*2+7,10) -> 9
G64: 王静 | H64: 11 | I64: =MIN((H64-10)*2+7,10) -> 9

Sheet 系统价值分（5%）
A1: 姓名 | B1: 车厢 | C1: 得分 | D1: 换算 | E1: 备注（多个系统则平均） | K1: 12月数据 | R1: 1月数据
A2: 张培进 | B2: 站台 | D2: =(IFERROR(VLOOKUP(A2,K:N,4,0),8) + IFERROR(VLOOKUP(A2,R:U,4,0),8))/2 -> 8 | K2: 姓名 | L2: 车厢 | M2: 得分 | N2: 换算 | O2: 备注（多个系统则平均） | R2: 姓名 | S2: 车厢 | T2: 得分 | U2: 换算 | V2: 备注（多个系统则平均）
A3: 李向月 | B3: 学员全旅程服务-FC | D3: =(IFERROR(VLOOKUP(A3,K:N,4,0),8) + IFERROR(VLOOKUP(A3,R:U,4,0),8))/2 -> 8 | K3: 张培进 | L3: 站台 | N3: 8 | R3: 张培进 | S3: 站台 | U3: 8
A4: 王伊庆 | B4: 学员全旅程服务-FC | D4: =(IFERROR(VLOOKUP(A4,K:N,4,0),8) + IFERROR(VLOOKUP(A4,R:U,4,0),8))/2 -> 8 | K4: 李向月 | L4: 学员全旅程服务-FC | M4: -0.7 | N4: 8 | O4: 慧学系统 | R4: 李向月 | S4: 学员全旅程服务-FC | T4: -0.75 | U4: 8 | V4: 慧学系统
A5: 肖傲 | B5: 学员全旅程服务-FC | D5: =(IFERROR(VLOOKUP(A5,K:N,4,0),8) + IFERROR(VLOOKUP(A5,R:U,4,0),8))/2 -> 8 | K5: 王伊庆 | L5: 学员全旅程服务-FC | M5: -0.7 | N5: 8 | O5: 慧学系统 | R5: 王伊庆 | S5: 学员全旅程服务-FC | T5: -0.75 | U5: 8 | V5: 慧学系统
A6: 丁星杰 | B6: 站内营销-FC | D6: =(IFERROR(VLOOKUP(A6,K:N,4,0),8) + IFERROR(VLOOKUP(A6,R:U,4,0),8))/2 -> 10 | K6: 肖傲 | L6: 学员全旅程服务-FC | M6: -0.7 | N6: 8 | O6: 慧学系统 | R6: 肖傲 | S6: 学员全旅程服务-FC | T6: -0.75 | U6: 8 | V6: 慧学系统
A7: 张雷雷 | B7: 教学教研教务-FC | D7: =(IFERROR(VLOOKUP(A7,K:N,4,0),8) + IFERROR(VLOOKUP(A7,R:U,4,0),8))/2 -> 8 | K7: 丁星杰 | L7: 站内营销-FC | M7: 1 | N7: 10 | O7: 投放平台 | R7: 丁星杰 | S7: 站内营销-FC | T7: 1 | U7: 10 | V7: 投放平台
A8: 李占旭 | B8: 督导学服务-FC | D8: =(IFERROR(VLOOKUP(A8,K:N,4,0),8) + IFERROR(VLOOKUP(A8,R:U,4,0),8))/2 -> 9.49 | K8: 张雷雷 | L8: 教学教研教务-FC | M8: -0.75 | N8: 8 | O8: 慧刷题 | R8: 张雷雷 | S8: 教学教研教务-FC | T8: -0.62 | U8: 8 | V8: 慧刷题
A9: 王丽萍 | B9: 督导学服务-FC | D9: =(IFERROR(VLOOKUP(A9,K:N,4,0),8) + IFERROR(VLOOKUP(A9,R:U,4,0),8))/2 -> 9.49 | K9: 李占旭 | L9: 督导学服务-FC | M9: 0.38 | N9: 9.28 | O9: 哪吒 | R9: 李占旭 | S9: 督导学服务-FC | T9: 0.45 | U9: 9.7 | V9: 哪吒
A10: 茆伟 | B10: 三方能力对接-FC | D10: =(IFERROR(VLOOKUP(A10,K:N,4,0),8) + IFERROR(VLOOKUP(A10,R:U,4,0),8))/2 -> 10 | K10: 王丽萍 | L10: 督导学服务-FC | M10: 0.38 | N10: 9.28 | O10: 哪吒 | R10: 王丽萍 | S10: 督导学服务-FC | T10: 0.45 | U10: 9.7 | V10: 哪吒
A11: 王晨 | B11: 督导学服务-FC | D11: =(IFERROR(VLOOKUP(A11,K:N,4,0),8) + IFERROR(VLOOKUP(A11,R:U,4,0),8))/2 -> 9.49 | K11: 茆伟 | L11: 三方能力对接-FC | M11: 1 | N11: 10 | O11: 售后平台 | R11: 茆伟 | S11: 三方能力对接-FC | T11: 1 | U11: 10 | V11: 售后平台
A12: 程振国 | B12: 站内营销-FC | D12: =(IFERROR(VLOOKUP(A12,K:N,4,0),8) + IFERROR(VLOOKUP(A12,R:U,4,0),8))/2 -> 10 | K12: 王晨 | L12: 督导学服务-FC | M12: 0.38 | N12: 9.28 | O12: 哪吒 | R12: 王晨 | S12: 督导学服务-FC | T12: 0.45 | U12: 9.7 | V12: 哪吒
A13: 郭相磊 | B13: 学员全旅程服务-FC | D13: =(IFERROR(VLOOKUP(A13,K:N,4,0),8) + IFERROR(VLOOKUP(A13,R:U,4,0),8))/2 -> 8 | K13: 程振国 | L13: 站内营销-FC | M13: 1 | N13: 10 | O13: 投放平台 | R13: 程振国 | S13: 站内营销-FC | T13: 1 | U13: 10 | V13: 投放平台
A14: 闫涛 | B14: 站内营销-FC | D14: =(IFERROR(VLOOKUP(A14,K:N,4,0),8) + IFERROR(VLOOKUP(A14,R:U,4,0),8))/2 -> 10 | K14: 郭相磊 | L14: 学员全旅程服务-FC | M14: -0.7 | N14: 8 | O14: 慧学系统 | R14: 郭相磊 | S14: 学员全旅程服务-FC | T14: -0.75 | U14: 8 | V14: 慧学系统
A15: 高彦超 | B15: 三方能力对接-FC | D15: =(IFERROR(VLOOKUP(A15,K:N,4,0),8) + IFERROR(VLOOKUP(A15,R:U,4,0),8))/2 -> 10 | K15: 闫涛 | L15: 站内营销-FC | M15: 1 | N15: 10 | O15: 投放平台 | R15: 闫涛 | S15: 站内营销-FC | T15: 1 | U15: 10 | V15: 投放平台
A16: 李军 | B16: 其他 | D16: =(IFERROR(VLOOKUP(A16,K:N,4,0),8) + IFERROR(VLOOKUP(A16,R:U,4,0),8))/2 -> 8 | K16: 高彦超 | L16: 三方能力对接-FC | M16: 1 | N16: 10 | O16: 售后平台 | R16: 高彦超 | S16: 三方能力对接-FC | T16: 1 | U16: 10 | V16: 售后平台
A17: 刘志伟 | B17: 三方能力对接-FC | D17: =(IFERROR(VLOOKUP(A17,K:N,4,0),8) + IFERROR(VLOOKUP(A17,R:U,4,0),8))/2 -> 10 | K17: 李军 | L17: 其他 | N17: 8 | R17: 李军 | S17: 其他 | U17: 8
A18: 李思涵 | B18: 教学教研教务-FC | D18: =(IFERROR(VLOOKUP(A18,K:N,4,0),8) + IFERROR(VLOOKUP(A18,R:U,4,0),8))/2 -> 8 | K18: 刘志伟 | L18: 三方能力对接-FC | M18: 1 | N18: 10 | O18: 售后平台 | R18: 刘志伟 | S18: 三方能力对接-FC | T18: 1 | U18: 10 | V18: 售后平台
A19: 李澜楷 | B19: 站台 | D19: =(IFERROR(VLOOKUP(A19,K:N,4,0),8) + IFERROR(VLOOKUP(A19,R:U,4,0),8))/2 -> 8 | K19: 李思涵 | L19: 教学教研教务-FC | M19: -0.75 | N19: 8 | O19: 慧刷题 | R19: 李思涵 | S19: 教学教研教务-FC | T19: -0.62 | U19: 8 | V19: 慧刷题
A20: 李盼盼 | B20: 学科工具-FC | D20: =(IFERROR(VLOOKUP(A20,K:N,4,0),8) + IFERROR(VLOOKUP(A20,R:U,4,0),8))/2 -> 10 | K20: 李澜楷 | L20: 站台 | N20: 8 | R20: 李澜楷 | S20: 站台 | U20: 8
A21: 李阔 | B21: 站内营销-FC | D21: =(IFERROR(VLOOKUP(A21,K:N,4,0),8) + IFERROR(VLOOKUP(A21,R:U,4,0),8))/2 -> 10 | K21: 李盼盼 | L21: 学科工具-FC | M21: 1 | N21: 10 | O21: 择校+轻学 | R21: 李盼盼 | S21: 学科工具-FC | T21: 1 | U21: 10 | V21: 择校+轻学
A22: 王静 | B22: 其他 | D22: =(IFERROR(VLOOKUP(A22,K:N,4,0),8) + IFERROR(VLOOKUP(A22,R:U,4,0),8))/2 -> 8 | K22: 李阔 | L22: 站内营销-FC | M22: 1 | N22: 10 | O22: 投放平台 | R22: 李阔 | S22: 站内营销-FC | T22: 1 | U22: 10 | V22: 投放平台
A23: 袁荣 | B23: 其他 | D23: =(IFERROR(VLOOKUP(A23,K:N,4,0),8) + IFERROR(VLOOKUP(A23,R:U,4,0),8))/2 -> 8 | K23: 王静 | L23: 其他 | N23: 8 | R23: 王静 | S23: 其他 | U23: 8
A24: 朱艳梅 | B24: 教学教研教务-FC | D24: =(IFERROR(VLOOKUP(A24,K:N,4,0),8) + IFERROR(VLOOKUP(A24,R:U,4,0),8))/2 -> 8 | K24: 袁荣 | L24: 其他 | N24: 8 | R24: 袁荣 | S24: 其他 | U24: 8
A25: 李悦冰 | B25: 学员全旅程服务-FC | D25: =(IFERROR(VLOOKUP(A25,K:N,4,0),8) + IFERROR(VLOOKUP(A25,R:U,4,0),8))/2 -> 8 | K25: 朱艳梅 | L25: 教学教研教务-FC | M25: -0.75 | N25: 8 | O25: 慧刷题 | R25: 朱艳梅 | S25: 教学教研教务-FC | T25: -0.62 | U25: 8 | V25: 慧刷题
A26: 李红苗 | B26: 三方能力对接-FC | D26: =(IFERROR(VLOOKUP(A26,K:N,4,0),8) + IFERROR(VLOOKUP(A26,R:U,4,0),8))/2 -> 10 | K26: 李悦冰 | L26: 学员全旅程服务-FC | M26: -0.7 | N26: 8 | O26: 慧学系统 | R26: 李悦冰 | S26: 学员全旅程服务-FC | T26: -0.75 | U26: 8 | V26: 慧学系统
A27: 杨爱学 | B27: 督导学服务-FC | D27: =(IFERROR(VLOOKUP(A27,K:N,4,0),8) + IFERROR(VLOOKUP(A27,R:U,4,0),8))/2 -> 9.49 | K27: 李红苗 | L27: 三方能力对接-FC | M27: 1 | N27: 10 | O27: 售后平台 | R27: 李红苗 | S27: 三方能力对接-FC | T27: 1 | U27: 10 | V27: 售后平台
A28: 王平 | B28: 站内营销-FC | D28: =(IFERROR(VLOOKUP(A28,K:N,4,0),8) + IFERROR(VLOOKUP(A28,R:U,4,0),8))/2 -> 10 | K28: 杨爱学 | L28: 督导学服务-FC | M28: 0.38 | N28: 9.28 | O28: 哪吒 | R28: 杨爱学 | S28: 督导学服务-FC | T28: 0.45 | U28: 9.7 | V28: 哪吒
A29: 王瑞娟 | B29: 学科工具-FC | D29: =(IFERROR(VLOOKUP(A29,K:N,4,0),8) + IFERROR(VLOOKUP(A29,R:U,4,0),8))/2 -> 10 | K29: 王平 | L29: 站内营销-FC | M29: 1 | N29: 10 | O29: 投放平台 | R29: 王平 | S29: 站内营销-FC | T29: 1 | U29: 10 | V29: 投放平台
A30: 赵丙圯 | B30: 学员全旅程服务-FC | D30: =(IFERROR(VLOOKUP(A30,K:N,4,0),8) + IFERROR(VLOOKUP(A30,R:U,4,0),8))/2 -> 8 | K30: 王瑞娟 | L30: 学科工具-FC | M30: 1 | N30: 10 | O30: 择校+轻学 | R30: 王瑞娟 | S30: 学科工具-FC | T30: 1 | U30: 10 | V30: 择校+轻学
A31: 刘昊恺 | B31: 站内营销-FC | D31: =(IFERROR(VLOOKUP(A31,K:N,4,0),8) + IFERROR(VLOOKUP(A31,R:U,4,0),8))/2 -> 10 | K31: 赵丙圯 | L31: 学员全旅程服务-FC | M31: -0.7 | N31: 8 | O31: 慧学系统 | R31: 赵丙圯 | S31: 学员全旅程服务-FC | T31: -0.75 | U31: 8 | V31: 慧学系统
A32: 仝光华 | B32: 学员全旅程服务-FC | D32: =(IFERROR(VLOOKUP(A32,K:N,4,0),8) + IFERROR(VLOOKUP(A32,R:U,4,0),8))/2 -> 8 | K32: 刘昊恺 | L32: 站内营销-FC | M32: 1 | N32: 10 | O32: 投放平台 | R32: 刘昊恺 | S32: 站内营销-FC | T32: 1 | U32: 10 | V32: 投放平台
A33: 任广琪 | B33: 教学教研教务-FC | D33: =(IFERROR(VLOOKUP(A33,K:N,4,0),8) + IFERROR(VLOOKUP(A33,R:U,4,0),8))/2 -> 8 | K33: 仝光华 | L33: 学员全旅程服务-FC | M33: -0.7 | N33: 8 | O33: 慧学系统 | R33: 仝光华 | S33: 学员全旅程服务-FC | T33: -0.75 | U33: 8 | V33: 慧学系统
A34: 刘宇祥 | B34: 教学教研教务-FC | D34: =(IFERROR(VLOOKUP(A34,K:N,4,0),8) + IFERROR(VLOOKUP(A34,R:U,4,0),8))/2 -> 8 | K34: 任广琪 | L34: 教学教研教务-FC | M34: -0.75 | N34: 8 | O34: 慧刷题 | R34: 任广琪 | S34: 教学教研教务-FC | T34: -0.62 | U34: 8 | V34: 慧刷题
A35: 刘红娇 | B35: 站台 | D35: =(IFERROR(VLOOKUP(A35,K:N,4,0),8) + IFERROR(VLOOKUP(A35,R:U,4,0),8))/2 -> 8 | K35: 刘宇祥 | L35: 教学教研教务-FC | M35: -0.75 | N35: 8 | O35: 慧刷题 | R35: 刘宇祥 | S35: 教学教研教务-FC | T35: -0.62 | U35: 8 | V35: 慧刷题
A36: 朱静娜 | B36: 站内营销-FC | D36: =(IFERROR(VLOOKUP(A36,K:N,4,0),8) + IFERROR(VLOOKUP(A36,R:U,4,0),8))/2 -> 10 | K36: 刘红娇 | L36: 站台 | N36: 8 | R36: 刘红娇 | S36: 站台 | U36: 8
A37: 李祥勇 | B37: 督导学服务-FC | D37: =(IFERROR(VLOOKUP(A37,K:N,4,0),8) + IFERROR(VLOOKUP(A37,R:U,4,0),8))/2 -> 9.49 | K37: 朱静娜 | L37: 站内营销-FC | M37: 1 | N37: 10 | O37: 投放平台 | R37: 朱静娜 | S37: 站内营销-FC | T37: 1 | U37: 10 | V37: 投放平台
A38: 熊苓军 | B38: 站台 | D38: =(IFERROR(VLOOKUP(A38,K:N,4,0),8) + IFERROR(VLOOKUP(A38,R:U,4,0),8))/2 -> 8 | K38: 李祥勇 | L38: 督导学服务-FC | M38: 0.38 | N38: 9.28 | O38: 哪吒 | R38: 李祥勇 | S38: 督导学服务-FC | T38: 0.45 | U38: 9.7 | V38: 哪吒
A39: 王宁 | B39: 站台 | D39: =(IFERROR(VLOOKUP(A39,K:N,4,0),8) + IFERROR(VLOOKUP(A39,R:U,4,0),8))/2 -> 8 | K39: 熊苓军 | L39: 站台 | N39: 8 | R39: 熊苓军 | S39: 站台 | U39: 8
A40: 王秉庵 | B40: 学科工具-FC | D40: =(IFERROR(VLOOKUP(A40,K:N,4,0),8) + IFERROR(VLOOKUP(A40,R:U,4,0),8))/2 -> 10 | K40: 王宁 | L40: 站台 | N40: 8 | R40: 王宁 | S40: 站台 | U40: 8
...
